Workbook
Name Slicer_Category: #N/A
Name Slicer_Order_Date_Year: #N/A
Name Slicer_Region: #N/A

Sheet Raw_Data
A1: Order ID | B1: Order Date | C1: Customer ID | D1: Product | E1: Category | F1: Quantity | G1: Price | H1: Revenue | I1: Region
A2: ORD0001 | B2: 2023-04-21 | C2: CUST059 | D2: Bag | E2: Accessories | F2: 1 | G2: 1205.7 | H2: 1205.7 | I2: Gauteng
A3: ORD0002 | B3: 2023-01-24 | C3: CUST119 | D3: Jacket | E3: Fashion | F3: 3 | G3: 1274.03 | H3: 3822.09 | I3: Gauteng
A4: ORD0003 | B4: 2023-08-23 | C4: CUST113 | D4: Bag | E4: Accessories | F4: 2 | G4: 1220.55 | H4: 2441.1 | I4: KwaZulu-Natal
A5: ORD0004 | B5: 2023-07-04 | C5: CUST109 | D5: Jacket | E5: Fashion | F5: 4 | G5: 1503.38 | H5: 6013.52 | I5: Gauteng
A6: ORD0005 | B6: 2023-01-02 | C6: CUST004 | D6: Shoes | E6: Fashion | F6: 3 | G6: 255.7 | H6: 767.1 | I6: Western Cape
A7: ORD0006 | B7: 2023-12-10 | C7: CUST012 | D7: Watch | E7: Accessories | F7: 1 | G7: 1996.53 | H7: 1996.53 | I7: KwaZulu-Natal
A8: ORD0007 | B8: 2023-07-26 | C8: CUST048 | D8: Table | E8: Home | F8: 3 | G8: 577.59 | H8: 1732.77 | I8: Western Cape
A9: ORD0008 | B9: 2023-05-12 | C9: CUST065 | D9: Jacket | E9: Fashion | F9: 5 | G9: 115.58 | H9: 577.9 | I9: Western Cape
A10: ORD0009 | B10: 2023-12-31 | C10: CUST026 | D10: Watch | E10: Accessories | F10: 3 | G10: 958.51 | H10: 2875.53 | I10: Eastern Cape
A11: ORD0010 | B11: 2023-01-14 | C11: CUST036 | D11: Headphones | E11: Electronics | F11: 2 | G11: 946.76 | H11: 1893.52 | I11: Eastern Cape
A12: ORD0011 | B12: 2023-12-29 | C12: CUST073 | D12: Headphones | E12: Electronics | F12: 3 | G12: 1052.33 | H12: 3156.99 | I12: Western Cape
A13: ORD0012 | B13: 2023-04-03 | C13: CUST034 | D13: Chair | E13: Home | F13: 2 | G13: 1384.57 | H13: 2769.14 | I13: Gauteng
... A501: ORD0500 | B501: 2023-12-29 | C501: CUST112 | D501: Watch | E501: Accessories | F501: 5 | G501: 1586.67 | H501: 7933.35 | I501: Eastern Cape

Sheet Clean_Data
A1: Order ID | B1: Order Date | C1: Customer ID | D1: Product | E1: Category | F1: Quantity | G1: Price | H1: Revenue | I1: Region | J1: Revenue2 | K1: Order Date (Month) | L1: Order Date(Year)
A2: ORD0001 | B2: 2023-04-21 | C2: CUST059 | D2: Bag | E2: Accessories | F2: 1 | G2: 1205.7 | H2: 1205.7 | I2: Gauteng | J2: =Sales_Data[[#This Row],[Quantity]] * Sales_Data[[#This Row],[Price]] -> 1205.7 | K2: =TEXT(Sales_Data[[#This Row],[Order Date]],"MMM") -> Apr | L2: =YEAR(Sales_Data[[#This Row],[Order Date]]) -> 2023
A3: ORD0002 | B3: 2023-01-24 | C3: CUST119 | D3: Jacket | E3: Fashion | F3: 3 | G3: 1274.03 | H3: 3822.09 | I3: Gauteng | J3: =Sales_Data[[#This Row],[Quantity]] * Sales_Data[[#This Row],[Price]] -> 3822.09 | K3: =TEXT(Sales_Data[[#This Row],[Order Date]],"MMM") -> Jan | L3: =YEAR(Sales_Data[[#This Row],[Order Date]]) -> 2023
A4: ORD0003 | B4: 2023-08-23 | C4: CUST113 | D4: Bag | E4: Accessories | F4: 2 | G4: 1220.55 | H4: 2441.1 | I4: KwaZulu-Natal | J4: =Sales_Data[[#This Row],[Quantity]] * Sales_Data[[#This Row],[Price]] -> 2441.1 | K4: =TEXT(Sales_Data[[#This Row],[Order Date]],"MMM") -> Aug | L4: =YEAR(Sales_Data[[#This Row],[Order Date]]) -> 2023
A5: ORD0004 | B5: 2023-07-04 | C5: CUST109 | D5: Jacket | E5: Fashion | F5: 4 | G5: 1503.38 | H5: 6013.52 | I5: Gauteng | J5: =Sales_Data[[#This Row],[Quantity]] * Sales_Data[[#This Row],[Price]] -> 6013.52 | K5: =TEXT(Sales_Data[[#This Row],[Order Date]],"MMM") -> Jul | L5: =YEAR(Sales_Data[[#This Row],[Order Date]]) -> 2023
A6: ORD0005 | B6: 2023-01-02 | C6: CUST004 | D6: Shoes | E6: Fashion | F6: 3 | G6: 255.7 | H6: 767.1 | I6: Western Cape | J6: =Sales_Data[[#This Row],[Quantity]] * Sales_Data[[#This Row],[Price]] -> 767.1 | K6: =TEXT(Sales_Data[[#This Row],[Order Date]],"MMM") -> Jan | L6: =YEAR(Sales_Data[[#This Row],[Order Date]]) -> 2023
A7: ORD0006 | B7: 2023-12-10 | C7: CUST012 | D7: Watch | E7: Accessories | F7: 1 | G7: 1996.53 | H7: 1996.53 | I7: KwaZulu-Natal | J7: =Sales_Data[[#This Row],[Quantity]] * Sales_Data[[#This Row],[Price]] -> 1996.53 | K7: =TEXT(Sales_Data[[#This Row],[Order Date]],"MMM") -> Dec | L7: =YEAR(Sales_Data[[#This Row],[Order Date]]) -> 2023
A8: ORD0007 | B8: 2023-07-26 | C8: CUST048 | D8: Table | E8: Home | F8: 3 | G8: 577.59 | H8: 1732.77 | I8: Western Cape | J8: =Sales_Data[[#This Row],[Quantity]] * Sales_Data[[#This Row],[Price]] -> 1732.77 | K8: =TEXT(Sales_Data[[#This Row],[Order Date]],"MMM") -> Jul | L8: =YEAR(Sales_Data[[#This Row],[Order Date]]) -> 2023
A9: ORD0008 | B9: 2023-05-12 | C9: CUST065 | D9: Jacket | E9: Fashion | F9: 5 | G9: 115.58 | H9: 577.9 | I9: Western Cape | J9: =Sales_Data[[#This Row],[Quantity]] * Sales_Data[[#This Row],[Price]] -> 577.9 | K9: =TEXT(Sales_Data[[#This Row],[Order Date]],"MMM") -> May | L9: =YEAR(Sales_Data[[#This Row],[Order Date]]) -> 2023
A10: ORD0009 | B10: 2023-12-31 | C10: CUST026 | D10: Watch | E10: Accessories | F10: 3 | G10: 958.51 | H10: 2875.53 | I10: Eastern Cape | J10: =Sales_Data[[#This Row],[Quantity]] * Sales_Data[[#This Row],[Price]] -> 2875.53 | K10: =TEXT(Sales_Data[[#This Row],[Order Date]],"MMM") -> Dec | L10: =YEAR(Sales_Data[[#This Row],[Order Date]]) -> 2023
A11: ORD0010 | B11: 2023-01-14 | C11: CUST036 | D11: Headphones | E11: Electronics | F11: 2 | G11: 946.76 | H11: 1893.52 | I11: Eastern Cape | J11: =Sales_Data[[#This Row],[Quantity]] * Sales_Data[[#This Row],[Price]] -> 1893.52 | K11: =TEXT(Sales_Data[[#This Row],[Order Date]],"MMM") -> Jan | L11: =YEAR(Sales_Data[[#This Row],[Order Date]]) -> 2023
A12: ORD0011 | B12: 2023-12-29 | C12: CUST073 | D12: Headphones | E12: Electronics | F12: 3 | G12: 1052.33 | H12: 3156.99 | I12: Western Cape | J12: =Sales_Data[[#This Row],[Quantity]] * Sales_Data[[#This Row],[Price]] -> 3156.99 | K12: =TEXT(Sales_Data[[#This Row],[Order Date]],"MMM") -> Dec | L12: =YEAR(Sales_Data[[#This Row],[Order Date]]) -> 2023
A13: ORD0012 | B13: 2023-04-03 | C13: CUST034 | D13: Chair | E13: Home | F13: 2 | G13: 1384.57 | H13: 2769.14 | I13: Gauteng | J13: =Sales_Data[[#This Row],[Quantity]] * Sales_Data[[#This Row],[Price]] -> 2769.14 | K13: =TEXT(Sales_Data[[#This Row],[Order Date]],"MMM") -> Apr | L13: =YEAR(Sales_Data[[#This Row],[Order Date]]) -> 2023
... A501: ORD0500 | B501: 2023-12-29 | C501: CUST112 | D501: Watch | E501: Accessories | F501: 5 | G501: 1586.67 | H501: 7933.35 | I501: Eastern Cape | J501: =Sales_Data[[#This Row],[Quantity]] * Sales_Data[[#This Row],[Price]] -> 7933.35 | K501: =TEXT(Sales_Data[[#This Row],[Order Date]],"MMM") -> Dec | L501: =YEAR(Sales_Data[[#This Row],[Order Date]]) -> 2023

Sheet Calculations
A2: Metric | B2: Numbers
A3: Total Revenue | B3: =SUM(Sales_Data[Revenue]) -> 1576075.3
A4: Total Orders | B4: =COUNTA(Sales_Data[Order ID]) -> 500
A5: Total Customers | B5: =COUNTA(_xlfn.UNIQUE(Sales_Data[Customer ID])) -> 119
A6: Average Order Value(AOV) | B6: =B3 / B4 -> 3152.1505
A7: Unique Customers | B7: =COUNTA(_xlfn.UNIQUE(Sales_Data[Customer ID])) -> 119

Sheet Pivot_Tables
A1: Row Labels | B1: Sum of Revenue
A2: 2023 | B2: 1442514.1
A3: Feb | B3: 95029.06
A4: Mar | B4: 143256.64
A5: Apr | B5: 117686.26
A6: May | B6: 156888.15
A7: Jun | B7: 143507.14
A8: Jul | B8: 139446.67
A9: Aug | B9: 101637.45
A10: Sept | B10: 166405.83
A11: Oct | B11: 151110.65
A12: Nov | B12: 93037.99
A13: Dec | B13: 134508.22
A14: Grand Total | B14: 1442514.1
A20: Row Labels | B20: Sum of Revenue
A21: Electronics | B21: 583459.87
A22: Fashion | B22: 375887.67
A23: Accessories | B23: 338766.59
A24: Home | B24: 277961.13
A25: Grand Total | B25: 1576075.3
A37: Row Labels | B37: Sum of Revenue
A38: KwaZulu-Natal | B38: 404562.29
A39: Gauteng | B39: 403924.39
A40: Western Cape | B40: 383859.55
A41: Eastern Cape | B41: 383729.03
A42: Grand Total | B42: 1576075.3
A52: Row Labels | B52: Sum of Revenue
A53: CUST039 | B53: 21808.64
A54: CUST096 | B54: 22324.13
A55: CUST113 | B55: 22618.83
A56: CUST120 | B56: 24726.33
A57: CUST043 | B57: 24917.92
A58: CUST062 | B58: 26100.53
A59: CUST008 | B59: 31593.42
A60: CUST044 | B60: 36952.53
A61: CUST112 | B61: 37946.43
A62: CUST076 | B62: 41586.28
A63: Grand Total | B63: 290575.04
A69: Sum of Revenue
A70: 1576075.3
...

Sheet Sheet4
A3: Distinct Count of Customer ID
A4: 119

Sheet Dashboard
C12: =GETPIVOTDATA("Revenue",Pivot_Tables!$A$69) -> 1576075.3 | D12: =GETPIVOTDATA("Order ID",Pivot_Tables!$A$72) -> 500 | H12: =GETPIVOTDATA("[Measures].[Distinct Count of Customer ID]",Sheet4!$A$3) -> 119 | L12: =GETPIVOTDATA("Sum of Revenue",Pivot_Tables!$A$78)/GETPIVOTDATA("Count of Order ID",Pivot_Tables!$A$78) -> 3152.1505
